Workbook

Sheet Read Me
A1: IntelliQE · API Pattern Validation Pack
A2: A catalogue of API patterns, an import-ready endpoint list, and a tracker for validating each pattern through IntelliQE API Automation.
A5: What this workbook is for
A6: You want to prove that IntelliQE's API Automation handles every shape of API your teams will throw at it. This pack lists 68 distinct API patterns, tells you which ones the platform supports today, gives you a runnable public endpoint for each pattern that has one, and leaves you columns to record the result.
A8: The sheets
A9: API Patterns
A10: The master list. 68 patterns in 6 groups, each with an IntelliQE support rating (Native / Partial / Gap), a code-complete ETA, how to validate it, and the columns you fill in as you go. This is the sheet you work from.
A11: Endpoints (Import)
A12: 41 ready-to-run public endpoints, one per pattern, in exactly the column shape IntelliQE's spec importer expects. Upload this file in API Studio and the importer reads these rows as endpoints you can pick from.
A13: Scenario Matrix
A14: The 22 scenario rows the generator works through for every endpoint, and which coverage depth unlocks each one. Use it to check that a run produced what it should have.
A15: Check Types
... A43: They are well-known public sandboxes (httpbin.org, jsonplaceholder.typicode.com, dummyjson.com, reqres.in, api.restful-api.dev, postman-echo.com, api.github.com, countries.trevorblades.com, dataaccess.net). They were chosen from documentation, not pinged from this machine - confirm each one is reachable from your network and not blocked by a corporate proxy before you treat a failure as an IntelliQE defect. Credentials shown are the public throwaway values those sandboxes document; none are real secrets.

Sheet API Patterns
A1: API Patterns · catalogue, delivery status and validation tracker
A2: 68 patterns · Support = what the code does today · ETA = code-complete date (09/09/2026 for every Native or Partial pattern; TBD for the 12 gaps) · amber cells are yours · row 4 is a worked example, delete it.
A3: ID | B3: Group | C3: API Pattern | D3: What it looks like | E3: Method(s) | F3: IntelliQE Support | G3: ETA | H3: How to validate it in IntelliQE / limitation | I3: Suggested Depth | J3: Sample | K3: Validation Status | L3: Scenarios Generated | M3: Scenarios Passed | N3: Pass % | O3: Run Date | P3: Notes / Defect
A4: P00 | B4: — worked example — | C4: Single resource read by id | D4: GET /resource/{id} returns one object | E4: GET | F4: Native | G4: 46274 | H4: Ran E02 at Standard depth: 13 scenarios designed, all rendered, 12 passed. | I4: Standard | J4: E02 | K4: Pass | L4: 13 | M4: 12 | N4: =IFERROR(M4/L4,"") | O4: 46275 | P4: One 405 case failed - the sandbox returns 404 for a wrong verb. Not an IntelliQE defect.
A5: P01 | B5: Core REST / CRUD | C5: Collection read (list) | D5: GET a collection URL, returns an array or an envelope of records | E5: GET | F5: Native | G5: 46274 | H5: Straightforward. Use jsonArrayNotEmpty on the root (path "") plus jsonProperty type checks on element 0. | I5: Standard | J5: E01 | K5: Not started | N5: =IFERROR(M5/L5,"")
A6: P02 | B6: Core REST / CRUD | C6: Single resource read by id | D6: GET /resource/{id} returns one object | E6: GET | F6: Native | G6: 46274 | H6: The canonical case. Happy path plus a 404 for an impossible id are both [core] rows. | I6: Standard | J6: E02 | K6: Not started | N6: =IFERROR(M6/L6,"")
A7: P03 | B7: Core REST / CRUD | C7: Create (POST) | D7: POST a JSON body, returns 201 and the created record (often with a Location header) | E7: POST | F7: Native | G7: 46274 | H7: Set Expected Status to 201 so the happy-path case asserts exactly that. Payload negative rows unlock automatically for write methods. | I7: Standard | J7: E03 | K7: Not started | N7: =IFERROR(M7/L7,"")
A8: P04 | B8: Core REST / CRUD | C8: Full replace (PUT) | D8: PUT the complete representation of a resource | E8: PUT | F8: Native | G8: 46274 | H8: Same as POST. The [deep] idempotency row applies here: the same request twice, the same status. | I8: Standard | J8: E04 | K8: Not started | N8: =IFERROR(M8/L8,"")
A9: P05 | B9: Core REST / CRUD | C9: Partial update (PATCH) | D9: PATCH a subset of fields | E9: PATCH | F9: Native | G9: 46274 | H9: Supply only the fields you are changing in the Body field; the generator derives missing-field negatives from it. | I9: Standard | J9: E05 | K9: Not started | N9: =IFERROR(M9/L9,"")
A10: P06 | B10: Core REST / CRUD | C10: Delete (DELETE) | D10: DELETE a resource, often 204 with no response body | E10: DELETE | F10: Partial | G10: 46274 | H10: A 204 has no body, so any jsonProperty check throws 'Expected a JSON response body'. Keep this endpoint on Essential depth, or trim the generated spec to status/header checks. | I10: Essential | J10: E06 | K10: Not started | N10: =IFERROR(M10/L10,"")
A11: P07 | B11: Core REST / CRUD | C11: Nested / sub-resource | D11: GET /parent/{id}/children | E11: GET | F11: Native | G11: 46274 | H11: Works as an ordinary URL. Assert the array and a parent-id field on element 0. | I11: Standard | J11: E07 | K11: Not started | N11: =IFERROR(M11/L11,"")
A12: P08 | B12: Core REST / CRUD | C12: HEAD (headers only) | D12: HEAD returns status and headers, never a body | E12: HEAD | F12: Partial | G12: 46274 | H12: Rendered with request.head(). Only status, header and responseTime checks are meaningful; strip any jsonProperty the generator adds. | I12: Essential | J12: E08 | K12: Not started | N12: =IFERROR(M12/L12,"")
A13: P09 | B13: Core REST / CRUD | C13: OPTIONS / CORS preflight | D13: OPTIONS returns Allow and Access-Control-* headers | E13: OPTIONS | F13: Partial | G13: 46274 | H13: Not one of Playwright's named verbs, so it renders through request.fetch(). Assert the Allow and Access-Control-Allow-Methods headers. | I13: Essential | J13: E09 | K13: Not started | N13: =IFERROR(M13/L13,"")
A14: P10 | B14: Core REST / CRUD | C14: Non-standard verb | D14: PURGE, LOCK, REPORT and other custom verbs | E14: Other | F14: Partial | G14: 46274 | H14: Also routed through request.fetch(). Accepted as long as the verb is alphabetic - digits and dashes are stripped by the payload sanitiser. | I14: Essential | K14: Not started | N14: =IFERROR(M14/L14,"")
A15: P11 | B15: Collections & Query | C15: Query-parameter filtering | D15: ?status=active&userId=1 | E15: GET | F15: Native | G15: 46274 | H15: Put the filter in the URL. The [wide] 'unknown query parameter' row checks the API ignores junk params instead of returning 500. | I15: Standard | J15: E10 | K15: Not started | N15: =IFERROR(M15/L15,"")
A16: P12 | B16: Collections & Query | C16: Offset / limit pagination | D16: ?limit=10&skip=20 or ?offset= | E16: GET | F16: Native | G16: 46274 | H16: Assert the page size with a jsonProperty type/array check, and the total/limit/skip fields from the envelope. | I16: Standard | J16: E11 | K16: Not started | N16: =IFERROR(M16/L16,"")
A17: P13 | B17: Collections & Query | C17: Page / size pagination | D17: ?page=2&per_page=20 | E17: GET | F17: Native | G17: 46274 | H17: Same as offset/limit. Add a negative case for page=0 or a page beyond the end. | I17: Standard | J17: E12 | K17: Not started | N17: =IFERROR(M17/L17,"")
A18: P14 | B18: Collections & Query | C18: Cursor / keyset pagination | D18: The response returns next_cursor, used in the following request | E18: GET | F18: Gap | G18: TBD | H18: NOT supported today: every generated spec is independently runnable with no shared state, so a cursor from call 1 cannot feed call 2. Validate page 1 only, or paste a known cursor into a second endpoint row. | I18: Essential | K18: Not started | N18: =IFERROR(M18/L18,"")
A19: P15 | B19: Collections & Query | C19: Link-header pagination (RFC 5988) | D19: Link: <...>; rel="next" | E19: GET | F19: Partial | G19: 46274 | H19: The Link header can be asserted with a header/contains check, but the generator cannot follow it to the next page. | I19: Standard | J19: E13 | K19: Not started | N19: =IFERROR(M19/L19,"")
A20: P16 | B20: Collections & Query | C20: Sorting & field selection | D20: ?_sort=id&_order=desc, ?fields=id,name | E20: GET | F20: Native | G20: 46274 | H20: Assert ordering by checking the literal value of element 0 with jsonProperty value. | I20: Standard | J20: E14 | K20: Not started | N20: =IFERROR(M20/L20,"")
A21: P17 | B21: Collections & Query | C21: Full-text search | D21: ?q=phone | E21: GET | F21: Native | G21: 46274 | H21: Assert the result array is non-empty and that a returned field contains the search term (bodyContains). | I21: Standard | J21: E15 | K21: Not started | N21: =IFERROR(M21/L21,"")
A22: P18 | B22: Collections & Query | C22: Empty result set | D22: 200 with [] or an envelope with total=0 | E22: GET | F22: Native | G22: 46274 | H22: An important negative-adjacent case: assert 200 (not 404) and total=0. jsonArrayNotEmpty must NOT be used here. | I22: Standard | J22: E16 | K22: Not started | N22: =IFERROR(M22/L22,"")
A23: P19 | B23: Collections & Query | C23: Bulk / batch write | D23: POST an array of records in one call | E23: POST | F23: Native | G23: 46274 | H23: Put the array in the Body field. All payload negatives apply. | I23: Standard | J23: E17 | K23: Not started | N23: =IFERROR(M23/L23,"")
A24: P20 | B24: Collections & Query | C24: Large payload / many records | D24: Thousands of records, or a multi-MB body | E24: Any | F24: Partial | G24: 46274 | H24: The request body and the expected response are each capped at 20,000 characters by the payload sanitiser; longer samples are truncated before the generator sees them. | I24: Essential | K24: Not started | N24: =IFERROR(M24/L24,"")
A25: P21 | B25: Content & Protocol | C25: JSON request / response | D25: application/json both ways | E25: Any | F25: Native | G25: 46274 | H25: The default and best-supported shape - all eight check kinds apply. | I25: Exhaustive | J25: E18 | K25: Not started | N25: =IFERROR(M25/L25,"")
A26: P22 | B26: Content & Protocol | C26: Bare-array root response | D26: The body is a top-level JSON array | E26: GET | F26: Native | G26: 46274 | H26: Use jsonArrayNotEmpty with path "" (an empty string means the root) and dotted paths like 0.id. | I26: Standard | J26: E18 | K26: Not started | N26: =IFERROR(M26/L26,"")
A27: P23 | B27: Content & Protocol | C27: Envelope response | D27: { data: [...], meta: {...}, errors: [...] } | E27: GET | F27: Native | G27: 46274 | H27: Dotted paths reach into the envelope: data.0.id, meta.total. | I27: Standard | J27: E19 | K27: Not started | N27: =IFERROR(M27/L27,"")
A28: P24 | B28: Content & Protocol | C28: Deeply nested JSON | D28: Objects inside arrays inside objects | E28: GET | F28: Native | G28: 46274 | H28: Dot notation with array indices - products.0.title. The renderer walks it with a generated getPath() helper. | I28: Standard | J28: E20 | K28: Not started | N28: =IFERROR(M28/L28,"")
A29: P25 | B29: Content & Protocol | C29: XML / SOAP | D29: text/xml or application/soap+xml, both ways | E29: POST | F29: Partial | G29: 46274 | H29: Runs, but only status, header and bodyContains assertions apply - there is no XPath check kind and no JSON parse. Set Content-Type and SOAPAction yourself in Headers. | I29: Essential | J29: E21 | K29: Not started | N29: =IFERROR(M29/L29,"")
A30: P26 | B30: Content & Protocol | C30: Plain text / HTML response | D30: text/plain or text/html | E30: GET | F30: Partial | G30: 46274 | H30: Assert with bodyContains and a content-type header check. jsonProperty will throw on a non-JSON body. | I30: Essential | J30: E22 | K30: Not started | N30: =IFERROR(M30/L30,"")
A31: P27 | B31: Content & Protocol | C31: Form-urlencoded body | D31: a=1&b=2 with application/x-www-form-urlencoded | E31: POST | F31: Partial | G31: 46274 | H31: The body is sent verbatim as a string, so this works - but you MUST add the Content-Type header yourself; the renderer defaults to application/json whenever one is absent. | I31: Essential | J31: E23 | K31: Not started | N31: =IFERROR(M31/L31,"")
A32: P28 | B32: Content & Protocol | C32: Multipart / file upload | D32: multipart/form-data with a file part | E32: POST | F32: Gap | G32: TBD | H32: NOT supported: the renderer only ever emits a string 'data' option, never Playwright's multipart option. Covering this needs a code change. | K32: Not started | N32: =IFERROR(M32/L32,"")
A33: P29 | B33: Content & Protocol | C33: Binary / file download | D33: A PDF, PNG or ZIP response body | E33: GET | F33: Partial | G33: 46274 | H33: Assert status, content-type and content-length. There is no byte-size or checksum check kind. | I33: Essential | J33: E24 | K33: Not started | N33: =IFERROR(M33/L33,"")
A34: P30 | B34: Content & Protocol | C34: Compressed response (gzip/br) | D34: Content-Encoding: gzip | E34: GET | F34: Native | G34: 46274 | H34: Playwright's request context decompresses transparently, so ordinary JSON checks work. | I34: Essential | J34: E25 | K34: Not started | N34: =IFERROR(M34/L34,"")
A35: P31 | B35: Content & Protocol | C35: GraphQL | D35: One POST endpoint, always 200, errors carried in the body | E35: POST | F35: Partial | G35: 46274 | H35: Works as a plain POST with a JSON body. Assert the data.* fields - status 200 alone is not enough here, because a GraphQL error is still a 200. | I35: Standard | J35: E26 | K35: Not started | N35: =IFERROR(M35/L35,"")
A36: P32 | B36: Content & Protocol | C36: gRPC / gRPC-Web | D36: Protobuf over HTTP/2 | E36: POST | F36: Gap | G36: TBD | H36: NOT supported: no proto handling and no binary framing in the request renderer. | K36: Not started | N36: =IFERROR(M36/L36,"")
A37: P33 | B37: Content & Protocol | C37: WebSocket / SSE streaming | D37: A long-lived connection carrying streamed events | E37: GET | F37: Gap | G37: TBD | H37: NOT supported: the Playwright request context is strictly request/response. | K37: Not started | N37: =IFERROR(M37/L37,"")
A38: P34 | B38: Auth & Security | C38: Public / no auth | D38: No credential required | E38: Any | F38: Native | G38: 46274 | H38: Set Auth type to 'none'. The whole AUTH block of the scenario matrix is then skipped automatically. | I38: Standard | J38: E27 | K38: Not started | N38: =IFERROR(M38/L38,"")
A39: P35 | B39: Auth & Security | C39: Bearer / JWT (static token) | D39: Authorization: Bearer <token> | E39: Any | F39: Native | G39: 46274 | H39: Paste the token WITHOUT the 'Bearer ' prefix - the renderer adds the scheme. A pasted header line or scheme is stripped defensively. | I39: Standard | J39: E28 | K39: Not started | N39: =IFERROR(M39/L39,"")
A40: P36 | B40: Auth & Security | C40: Basic auth | D40: Authorization: Basic base64(user:pass) | E40: Any | F40: Native | G40: 46274 | H40: Enter it as username:password in plain text; the renderer base64-encodes it. | I40: Standard | J40: E29 | K40: Not started | N40: =IFERROR(M40/L40,"")
...

Sheet Endpoints (Import)
A1: Endpoints (Import) · one endpoint per row, ready for API Studio
A2: Column names match what the IntelliQE spec importer looks for. Upload this workbook - or this sheet saved as .csv - via Import in API Studio.
A3: Ref | B3: Title | C3: Method | D3: URL | E3: Headers | F3: Auth Type | G3: Auth Value | H3: Body | I3: Expected Status | J3: Expected Response | K3: Pattern
A4: E01 | B4: GET /posts - list all posts | C4: GET | D4: https://jsonplaceholder.typicode.com/posts | E4: Accept: application/json | F4: none | I4: 200 | J4: [{"userId":1,"id":1,"title":"...","body":"..."}] | K4: P01
A5: E02 | B5: GET /posts/1 - read one post | C5: GET | D5: https://jsonplaceholder.typicode.com/posts/1 | E5: Accept: application/json | F5: none | I5: 200 | J5: {"userId":1,"id":1,"title":"...","body":"..."} | K5: P02
A6: E03 | B6: POST /posts - create a post | C6: POST | D6: https://jsonplaceholder.typicode.com/posts | E6: Content-Type: application/json | F6: none | H6: {"title":"IntelliQE pattern check","body":"created by API Studio","userId":1} | I6: 201 | J6: {"id":101,"title":"IntelliQE pattern check","body":"created by API Studio","userId":1} | K6: P03
A7: E04 | B7: PUT /posts/1 - full replace | C7: PUT | D7: https://jsonplaceholder.typicode.com/posts/1 | E7: Content-Type: application/json | F7: none | H7: {"id":1,"title":"replaced","body":"replaced body","userId":1} | I7: 200 | J7: {"id":1,"title":"replaced","body":"replaced body","userId":1} | K7: P04
A8: E05 | B8: PATCH /posts/1 - partial update | C8: PATCH | D8: https://jsonplaceholder.typicode.com/posts/1 | E8: Content-Type: application/json | F8: none | H8: {"title":"patched title"} | I8: 200 | J8: {"id":1,"title":"patched title","userId":1} | K8: P05
A9: E06 | B9: DELETE /posts/1 - remove a post | C9: DELETE | D9: https://jsonplaceholder.typicode.com/posts/1 | F9: none | I9: 200 | J9: {} | K9: P06
A10: E07 | B10: GET /posts/1/comments - nested sub-resource | C10: GET | D10: https://jsonplaceholder.typicode.com/posts/1/comments | E10: Accept: application/json | F10: none | I10: 200 | J10: [{"postId":1,"id":1,"name":"...","email":"...","body":"..."}] | K10: P07
A11: E08 | B11: HEAD /get - headers only, no body | C11: HEAD | D11: https://httpbin.org/get | F11: none | I11: 200 | K11: P08
A12: E09 | B12: OPTIONS /get - CORS preflight | C12: OPTIONS | D12: https://httpbin.org/get | F12: none | I12: 200 | K12: P09
A13: E10 | B13: GET /comments?postId=1 - query filtering | C13: GET | D13: https://jsonplaceholder.typicode.com/comments?postId=1 | E13: Accept: application/json | F13: none | I13: 200 | J13: [{"postId":1,"id":1,"email":"..."}] | K13: P11
A14: E11 | B14: GET /products?limit=10&skip=20 - offset pagination | C14: GET | D14: https://dummyjson.com/products?limit=10&skip=20 | E14: Accept: application/json | F14: none | I14: 200 | J14: {"products":[{"id":21,"title":"..."}],"total":194,"skip":20,"limit":10} | K14: P12
A15: E12 | B15: GET /api/users?page=2 - page pagination | C15: GET | D15: https://reqres.in/api/users?page=2 | E15: x-api-key: reqres-free-v1 | F15: none | I15: 200 | J15: {"page":2,"per_page":6,"total":12,"data":[{"id":7,"email":"..."}]} | K15: P13
A16: E13 | B16: GET GitHub issues - Link-header pagination | C16: GET | D16: https://api.github.com/repos/microsoft/playwright/issues?per_page=5 | E16: Accept: application/vnd.github+json | F16: none | I16: 200 | J16: [{"id":1,"number":1,"title":"...","state":"open"}] | K16: P15
A17: E14 | B17: GET /posts sorted desc, limit 5 | C17: GET | D17: https://jsonplaceholder.typicode.com/posts?_sort=id&_order=desc&_limit=5 | E17: Accept: application/json | F17: none | I17: 200 | J17: [{"id":100,"title":"..."}] | K17: P16
A18: E15 | B18: GET /products/search?q=phone - full-text search | C18: GET | D18: https://dummyjson.com/products/search?q=phone | E18: Accept: application/json | F18: none | I18: 200 | J18: {"products":[{"id":1,"title":"..."}],"total":1,"skip":0,"limit":1} | K18: P17
A19: E16 | B19: GET /comments?postId=99999999 - empty result set | C19: GET | D19: https://jsonplaceholder.typicode.com/comments?postId=99999999 | E19: Accept: application/json | F19: none | I19: 200 | J19: [] | K19: P18
A20: E17 | B20: POST /objects - create with a nested body | C20: POST | D20: https://api.restful-api.dev/objects | E20: Content-Type: application/json | F20: none | H20: {"name":"IntelliQE Probe","data":{"year":2026,"price":1499.99,"CPU model":"M4","Hard disk size":"1 TB"}} | I20: 200 | J20: {"id":"ff8081","name":"IntelliQE Probe","createdAt":"2026-01-01T00:00:00.000+00:00","data":{"year":2026,"price":1499.99}} | K20: P19
A21: E18 | B21: GET /objects - bare array root | C21: GET | D21: https://api.restful-api.dev/objects | E21: Accept: application/json | F21: none | I21: 200 | J21: [{"id":"1","name":"Google Pixel 6 Pro","data":{"color":"Cloudy White","capacity":"128 GB"}}] | K21: P22
A22: E19 | B22: GET /products?limit=5 - envelope response | C22: GET | D22: https://dummyjson.com/products?limit=5 | E22: Accept: application/json | F22: none | I22: 200 | J22: {"products":[{"id":1,"title":"..."}],"total":194,"skip":0,"limit":5} | K22: P23
A23: E20 | B23: GET /carts/1 - deeply nested JSON | C23: GET | D23: https://dummyjson.com/carts/1 | E23: Accept: application/json | F23: none | I23: 200 | J23: {"id":1,"products":[{"id":168,"title":"...","price":10,"quantity":3}],"total":103774,"userId":33} | K23: P24
A24: E21 | B24: POST NumberConversion - SOAP / XML | C24: POST | D24: https://www.dataaccess.net/webservicesserver/NumberConversion.wso | E24: Content-Type: text/xml; charset=utf-8 | F24: none | H24: <?xml version="1.0" encoding="utf-8"?><soap:Envelope xmlns:soap="http://schemas.xmlsoap.org/soap/envelope/"><soap:Body><NumberToWords xmlns="http://www.dataaccess.com/webservicesserver/"><ubiNum>500</ubiNum></NumberToWords></soap:Body></soap:Envelope> | I24: 200 | J24: <NumberToWordsResult>five hundred </NumberToWordsResult> | K24: P25
A25: E22 | B25: GET /html - HTML response body | C25: GET | D25: https://httpbin.org/html | E25: Accept: text/html | F25: none | I25: 200 | J25: <h1>Herman Melville - Moby-Dick</h1> | K25: P26
A26: E23 | B26: POST /post - form-urlencoded body | C26: POST | D26: https://httpbin.org/post | E26: Content-Type: application/x-www-form-urlencoded | F26: none | H26: product=intelliqe&mode=api | I26: 200 | J26: {"form":{"product":"intelliqe","mode":"api"}} | K26: P27
A27: E24 | B27: GET /image/png - binary download | C27: GET | D27: https://httpbin.org/image/png | E27: Accept: image/png | F27: none | I27: 200 | K27: P29
A28: E25 | B28: GET /gzip - compressed response | C28: GET | D28: https://httpbin.org/gzip | E28: Accept-Encoding: gzip | F28: none | I28: 200 | J28: {"gzipped":true,"method":"GET"} | K28: P30
A29: E26 | B29: POST countries - GraphQL query | C29: POST | D29: https://countries.trevorblades.com/ | E29: Content-Type: application/json | F29: none | H29: {"query":"{ country(code: \"IN\") { name capital currency } }"} | I29: 200 | J29: {"data":{"country":{"name":"India","capital":"New Delhi","currency":"INR"}}} | K29: P31
A30: E27 | B30: GET /uuid - public, no auth | C30: GET | D30: https://httpbin.org/uuid | E30: Accept: application/json | F30: none | I30: 200 | J30: {"uuid":"a1b2c3d4-0000-0000-0000-000000000000"} | K30: P34
A31: E28 | B31: GET /bearer - bearer token accepted | C31: GET | D31: https://httpbin.org/bearer | E31: Accept: application/json | F31: bearer | G31: intelliqe-pattern-probe-token | I31: 200 | J31: {"authenticated":true,"token":"intelliqe-pattern-probe-token"} | K31: P35
A32: E29 | B32: GET /basic-auth - basic credentials | C32: GET | D32: https://httpbin.org/basic-auth/intelliqe/secret123 | E32: Accept: application/json | F32: basic | G32: intelliqe:secret123 | I32: 200 | J32: {"authenticated":true,"user":"intelliqe"} | K32: P36
A33: E30 | B33: GET /api/users/2 - API key header | C33: GET | D33: https://reqres.in/api/users/2 | F33: apikey | G33: reqres-free-v1 | I33: 200 | J33: {"data":{"id":2,"email":"...","first_name":"..."}} | K33: P37
A34: E31 | B34: GET /bearer with NO credential - expect 401 | C34: GET | D34: https://httpbin.org/bearer | E34: Accept: application/json | F34: none | I34: 401 | K34: P45
A35: E32 | B35: GET /delay/3 - slow response | C35: GET | D35: https://httpbin.org/delay/3 | E35: Accept: application/json | F35: none | I35: 200 | J35: {"url":"https://httpbin.org/delay/3"} | K35: P50
A36: E33 | B36: GET /redirect/1 - redirect is auto-followed | C36: GET | D36: https://httpbin.org/redirect/1 | E36: Accept: application/json | F36: none | I36: 200 | J36: {"url":"https://httpbin.org/get"} | K36: P51
A37: E34 | B37: GET /status/429 - rate-limit shape | C37: GET | D37: https://httpbin.org/status/429 | F37: none | I37: 429 | K37: P54
A38: E35 | B38: GET /posts/99999999 - unknown resource 404 | C38: GET | D38: https://jsonplaceholder.typicode.com/posts/99999999 | E38: Accept: application/json | F38: none | I38: 404 | J38: {} | K38: P57
A39: E36 | B39: GET /status/418 - explicit status contract | C39: GET | D39: https://httpbin.org/status/418 | F39: none | I39: 418 | K39: P58
A40: E37 | B40: GET /time/now - date / time response | C40: GET | D40: https://postman-echo.com/time/now | E40: Accept: text/plain | F40: none | I40: 200 | J40: Wed, 01 Jan 2026 00:00:00 GMT | K40: P62
...

Sheet Scenario Matrix
A1: Scenario Matrix · what the generator designs for every endpoint
A2: [core] always runs · [wide] needs Standard or Exhaustive · [deep] needs Exhaustive. Essential targets 4-6 cases, Standard 10-16, Exhaustive 16-28.
A3: Block | B3: Depth gate | C3: Scenario row | D3: What it asserts | E3: Applies to
A4: CONTRACT | B4: [core] | C4: Happy path | D4: The documented request returns the EXACT expected status code, plus the documented content-type. | E4: All methods
B5: [core] | C5: Response schema | D5: Each key field from the sample body exists, is of the right type, and equals the literal value where the sample is unambiguous. | E5: All methods
B6: [wide] | C6: Response time | D6: One responseTimeUnderMs guard on the happy path. | E6: All methods
B7: [deep] | C7: Content negotiation | D7: Accept: application/xml (or another unsupported type) returns 406, or JSON if the API ignores it. | E7: GET
A8: NEGATIVE / VALIDATION | B8: [core] | C8: Unknown resource | D8: A path id that cannot exist (for example 99999999) returns 404. | E8: All methods
B9: [core] | C9: Malformed path / query | D9: A non-numeric id where a number is required, or an invalid query value, returns 4xx. | E9: All methods
B10: [wide] | C10: Wrong HTTP method | D10: A different verb against the same URL returns 405, or a documented 4xx. | E10: All methods
B11: [wide] | C11: Unknown query parameter | D11: A junk query parameter is ignored (2xx) rather than causing a 500. | E11: All methods
B12: [deep] | C12: Trailing-slash / case variance | D12: A path variant does not produce a 500. | E12: All methods
A13: PAYLOAD | B13: [core] | C13: Missing required field | D13: Dropping one field the sample body carries returns 4xx. | E13: POST / PUT / PATCH
B14: [core] | C14: Malformed JSON | D14: A syntactically broken body returns 400. | E14: POST / PUT / PATCH
B15: [wide] | C15: Wrong field type | D15: A string where the sample has a number returns 4xx. | E15: POST / PUT / PATCH
B16: [wide] | C16: Empty body | D16: '{}' or an empty string returns 4xx. | E16: POST / PUT / PATCH
B17: [deep] | C17: Extra / unknown field | D17: An unexpected field is either rejected or safely ignored. | E17: POST / PUT / PATCH
B18: [deep] | C18: Oversized field | D18: A very long string in one field returns 4xx or 413. | E18: POST / PUT / PATCH
A19: AUTH | B19: [core] | C19: Valid credential | D19: The configured credential returns the expected 2xx. | E19: Only when auth is configured
B20: [core] | C20: No credential | D20: Sending no credential returns 401 or 403 - includeAuth:false strips the header. | E20: Only when auth is configured
B21: [wide] | C21: Malformed credential | D21: An explicit bogus Authorization header returns 401 or 403. | E21: Only when auth is configured
B22: [deep] | C22: Expired / revoked token | D22: A well-formed but invalid value returns 401. | E22: Only when auth is configured
A23: RESILIENCE | B23: [wide] | C23: Header sanity | D23: The content-type on the happy path is the documented type. | E23: All methods
B24: [deep] | C24: Injection probe | D24: A SQL- or script-shaped value returns a clean 4xx, and the raw payload is not echoed back. | E24: All methods
B25: [deep] | C25: Idempotency | D25: The documented request sent twice returns the same status. | E25: GET / PUT / DELETE

Sheet Check Types
A1: Check Types · the 8 assertions the renderer supports
A2: The generator returns typed JSON checks; a deterministic renderer turns each one into the Playwright line shown. Nothing outside this list can be asserted.
A3: Check kind | B3: What it asserts | C3: JSON the generator emits | D3: Rendered Playwright assertion
A4: status | B4: Assert the HTTP status code exactly, against a set, or below a ceiling. | C4: { "kind": "status", "equals": 200 } / "oneOf": [200,201] / "lessThan": 500 | D4: expect(response.status(), 'HTTP status code').toBe(200);
A5: ok | B5: Assert the response is any 2xx. | C5: { "kind": "ok" } | D5: expect(response.ok(), 'response should be successful (2xx)').toBeTruthy();
A6: notOk | B6: Assert the response is NOT 2xx - the safe assertion for a negative case. | C6: { "kind": "notOk" } | D6: expect(response.ok(), 'response should be a non-2xx error').toBeFalsy();
A7: jsonProperty | B7: Assert a dotted path in the JSON body exists, deep-equals a literal, or is of a given type (string|number|boolean|array|object). | C7: { "kind": "jsonProperty", "path": "data.0.id", "exists": true, "type": "number" } | D7: expect(getPath(body, 'data.0.id')).toBeDefined();
A8: jsonArrayNotEmpty | B8: Assert the body - or a path inside it - is a non-empty array. A path of "" means the JSON root. | C8: { "kind": "jsonArrayNotEmpty", "path": "" } | D8: expect(Array.isArray(body)).toBeTruthy(); expect((body || []).length).toBeGreaterThan(0);
A9: header | B9: Assert a response header is present, or contains a substring. Header names match case-insensitively. | C9: { "kind": "header", "name": "content-type", "contains": "application/json" } | D9: expect(String(response.headers()['content-type'] || '')).toContain('application/json');
A10: bodyContains | B10: Assert the RAW response text contains a substring - the only option for XML, HTML and plain text. | C10: { "kind": "bodyContains", "text": "five hundred" } | D10: expect(rawText).toContain('five hundred');
A11: responseTimeUnderMs | B11: Assert the round trip completed under N milliseconds. | C11: { "kind": "responseTimeUnderMs", "ms": 5000 } | D11: expect(elapsedMs, 'response time (ms)').toBeLessThan(5000);

Sheet Validation Summary
A1: Validation Summary
A2: Every figure below is a live formula over the API Patterns sheet, rows 5-72. The worked example in row 4 is excluded. Nothing here is typed in.
A4: Platform support across the 68 patterns
A5: Patterns catalogued | B5: =COUNTA('API Patterns'!$A$5:$A$72)
A6: Native - fully supported | B6: =COUNTIF('API Patterns'!$F$5:$F$72,"Native")
A7: Partial - works with a caveat | B7: =COUNTIF('API Patterns'!$F$5:$F$72,"Partial")
A8: Gap - not supported today | B8: =COUNTIF('API Patterns'!$F$5:$F$72,"Gap")
A9: Native + Partial as a share | B9: =IFERROR((COUNTIF('API Patterns'!$F$5:$F$72,"Native")+COUNTIF('API Patterns'!$F$5:$F$72,"Partial"))/COUNTA('API Patterns'!$A$5:$A$72),"")
A11: Delivery status (ETA column)
A12: Code complete - ETA set | B12: =COUNT('API Patterns'!$G$5:$G$72)
A13: Code complete on 09/09/2026 | B13: =COUNTIF('API Patterns'!$G$5:$G$72,DATE(2026,9,9))
A14: ETA still TBD | B14: =COUNTIF('API Patterns'!$G$5:$G$72,"TBD")
A15: Code complete as a share | B15: =IFERROR(COUNT('API Patterns'!$G$5:$G$72)/COUNTA('API Patterns'!$A$5:$A$72),"")
A17: Validation progress
A18: Not started | B18: =COUNTIF('API Patterns'!$K$5:$K$72,"Not started")
A19: Pass | B19: =COUNTIF('API Patterns'!$K$5:$K$72,"Pass")
A20: Partial | B20: =COUNTIF('API Patterns'!$K$5:$K$72,"Partial")
A21: Fail | B21: =COUNTIF('API Patterns'!$K$5:$K$72,"Fail")
A22: Blocked | B22: =COUNTIF('API Patterns'!$K$5:$K$72,"Blocked")
A23: N/A - known gap | B23: =COUNTIF('API Patterns'!$K$5:$K$72,"N/A - known gap")
A24: Patterns exercised | B24: =COUNTA('API Patterns'!$K$5:$K$72)-COUNTIF('API Patterns'!$K$5:$K$72,"Not started")
A25: Scenarios generated, total | B25: =SUM('API Patterns'!$L$5:$L$72)
A26: Scenarios passed, total | B26: =SUM('API Patterns'!$M$5:$M$72)
A27: Overall scenario pass rate | B27: =IFERROR(SUM('API Patterns'!$M$5:$M$72)/SUM('API Patterns'!$L$5:$L$72),"")
A29: By group
A30: Group | B30: Native | C30: Partial | D30: Gap
A31: Core REST / CRUD | B31: =COUNTIFS('API Patterns'!$B$5:$B$72,"Core REST / CRUD",'API Patterns'!$F$5:$F$72,"Native") | C31: =COUNTIFS('API Patterns'!$B$5:$B$72,"Core REST / CRUD",'API Patterns'!$F$5:$F$72,"Partial") | D31: =COUNTIFS('API Patterns'!$B$5:$B$72,"Core REST / CRUD",'API Patterns'!$F$5:$F$72,"Gap")
A32: Collections & Query | B32: =COUNTIFS('API Patterns'!$B$5:$B$72,"Collections & Query",'API Patterns'!$F$5:$F$72,"Native") | C32: =COUNTIFS('API Patterns'!$B$5:$B$72,"Collections & Query",'API Patterns'!$F$5:$F$72,"Partial") | D32: =COUNTIFS('API Patterns'!$B$5:$B$72,"Collections & Query",'API Patterns'!$F$5:$F$72,"Gap")
A33: Content & Protocol | B33: =COUNTIFS('API Patterns'!$B$5:$B$72,"Content & Protocol",'API Patterns'!$F$5:$F$72,"Native") | C33: =COUNTIFS('API Patterns'!$B$5:$B$72,"Content & Protocol",'API Patterns'!$F$5:$F$72,"Partial") | D33: =COUNTIFS('API Patterns'!$B$5:$B$72,"Content & Protocol",'API Patterns'!$F$5:$F$72,"Gap")
A34: Auth & Security | B34: =COUNTIFS('API Patterns'!$B$5:$B$72,"Auth & Security",'API Patterns'!$F$5:$F$72,"Native") | C34: =COUNTIFS('API Patterns'!$B$5:$B$72,"Auth & Security",'API Patterns'!$F$5:$F$72,"Partial") | D34: =COUNTIFS('API Patterns'!$B$5:$B$72,"Auth & Security",'API Patterns'!$F$5:$F$72,"Gap")
A35: Stateful & Async | B35: =COUNTIFS('API Patterns'!$B$5:$B$72,"Stateful & Async",'API Patterns'!$F$5:$F$72,"Native") | C35: =COUNTIFS('API Patterns'!$B$5:$B$72,"Stateful & Async",'API Patterns'!$F$5:$F$72,"Partial") | D35: =COUNTIFS('API Patterns'!$B$5:$B$72,"Stateful & Async",'API Patterns'!$F$5:$F$72,"Gap")
A36: Contract & Data | B36: =COUNTIFS('API Patterns'!$B$5:$B$72,"Contract & Data",'API Patterns'!$F$5:$F$72,"Native") | C36: =COUNTIFS('API Patterns'!$B$5:$B$72,"Contract & Data",'API Patterns'!$F$5:$F$72,"Partial") | D36: =COUNTIFS('API Patterns'!$B$5:$B$72,"Contract & Data",'API Patterns'!$F$5:$F$72,"Gap")
