Workbook

Sheet Assumptions
A1: ADA Compliance Suite - Roadmap Assumptions
A2: Every date in this workbook is driven by the four blue input cells below. Change them and the whole plan recalculates.
A4: INPUTS - edit these
A5: Project start date | B5: 46279 | C5: First working day. Must be a Monday-Friday.
A6: Engineers on the feature | B6: 2 | C6: Full-stack engineers assigned.
A7: Allocation per engineer | B7: 0.8 | C7: Share of time on this feature (0.8 = 80%).
A8: Effective capacity (person-days per working day) | B8: =B6*B7 -> 1.6 | C8: Engineers x allocation. Converts effort into elapsed days.
A10: DERIVED - do not edit
A11: Total effort (person-days) | B11: =SUM(Roadmap!F5:F43) -> 171 | C11: Sum of every task on the Roadmap tab.
A12: Elapsed working days | B12: =ROUNDUP(B11/B8,0) -> 107 | C12: Total effort divided by effective capacity.
A13: Elapsed calendar weeks | B13: =ROUND(B12/5,1) -> 21.4 | C13: Working days / 5. Excludes public holidays.
A14: MVP delivery (Milestone M3) | B14: =Milestones!D7 -> 46337 | C14: Accessibility + broken links + best practices.
A15: Full GA delivery (Milestone M7) | B15: =Milestones!D11 -> 46456 | C15: All nine checks, reporting and UI.
A17: BASIS OF ESTIMATE - read before quoting these dates
A18: - Effort figures are engineering estimates produced from a read of this codebase (backend/src/agents, backend/src/orchestrator, backend/src/services, frontend/src/pages/ChatPage.tsx). They are not quotes from the delivery team and have not been validated against team velocity.
A19: - The schedule models tasks as one sequential critical path at the stated capacity. Real execution will parallelise some tracks (e.g. frontend alongside backend checks), which pulls dates in; unplanned work and context-switching push them out. Treat the dates as a planning baseline, not a commitment.
A20: - Public holidays and leave are NOT modelled. WORKDAY() excludes weekends only. Subtract your own holiday days from the delivery dates.
A21: - Phase 3 (Visual & Design QA) carries the widest estimate range. Alignment, overlap and style-guide adherence have no off-the-shelf engine - unlike accessibility, which axe-core solves. If the Phase 0 spike shows a baseline-diff approach is needed, Phase 3 effort could grow materially.
A22: - Recommendation: ship Milestone M3 as release 1. Accessibility and broken links are the highest-confidence, highest-value checks and reach users in roughly a third of the total timeline.

Sheet Roadmap
A1: ADA Compliance Suite - Implementation Roadmap
A2: Dates are formulas driven by the Assumptions tab. Effort is in person-days; Duration converts that to elapsed working days at the assumed team capacity. Weekends excluded, public holidays are not.
A4: ID | B4: Phase | C4: Task | D4: Deliverable / definition of done | E4: Owner | F4: Effort (person-days) | G4: Duration (working days) | H4: Start | I4: End | J4: Milestone | K4: Confidence | L4: Key files / components | M4: Scope tag
A5: 1 | B5: Phase 0 - Discovery & Spike | C5: Spike: axe-core on a real target | D5: Run @axe-core/playwright against a live client site. Measure rule coverage, false-positive rate and runtime per page. | E5: Backend eng | F5: 3 | G5: =MAX(1,ROUNDUP(F5/Assumptions!$B$8,0)) -> 2 | H5: =Assumptions!$B$5 -> 46279 | I5: =WORKDAY(H5,G5-1) -> 46280 | K5: High | L5: backend/src/agents/exploreAgent.ts | M5: A11Y
A6: 2 | B6: Phase 0 - Discovery & Spike | C6: Spike: visual-check feasibility | D6: Decide geometry analysis (bounding boxes from the live DOM) vs rendered-baseline diff for alignment/overlap. Prototype both on one page. | E6: Backend eng | F6: 4 | G6: =MAX(1,ROUNDUP(F6/Assumptions!$B$8,0)) -> 3 | H6: =WORKDAY(I5,1) -> 46281 | I6: =WORKDAY(H6,G6-1) -> 46283 | K6: Low | L6: new: backend/src/services/ada-visual.service.ts | M6: ALIGN
A7: 3 | B7: Phase 0 - Discovery & Spike | C7: Scope lock & acceptance criteria | D7: Fix WCAG level (2.2 AA), viewport matrix, page-count cap per scan, per-tenant cost budget, and what counts as a pass. | E7: Product + QA lead | F7: 2 | G7: =MAX(1,ROUNDUP(F7/Assumptions!$B$8,0)) -> 2 | H7: =WORKDAY(I6,1) -> 46286 | I7: =WORKDAY(H7,G7-1) -> 46287 | K7: High | L7: backend/config/pipeline-definition.json | M7: INFRA
A8: 4 | B8: Phase 0 - Discovery & Spike | C8: Technical design & schema draft | D8: Design doc covering scan lifecycle, finding model, severity taxonomy and DB schema. Reviewed and signed off. | E8: Tech lead | F8: 3 | G8: =MAX(1,ROUNDUP(F8/Assumptions!$B$8,0)) -> 2 | H8: =WORKDAY(I7,1) -> 46288 | I8: =WORKDAY(H8,G8-1) -> 46289 | J8: M1 - Approach approved | K8: High | L8: backend/src/db.ts | M8: INFRA
A9: 5 | B9: Phase 1 - Scan Infrastructure | C9: Extract reusable crawler | D9: Promote the bounded crawl in exploreAgent.ts into ada-crawler.service.ts: auth-aware, same-origin, depth/page caps, emits a sitemap. | E9: Backend eng | F9: 6 | G9: =MAX(1,ROUNDUP(F9/Assumptions!$B$8,0)) -> 4 | H9: =WORKDAY(I8,1) -> 46290 | I9: =WORKDAY(H9,G9-1) -> 46295 | K9: High | L9: backend/src/agents/exploreAgent.ts -> services/ada-crawler.service.ts | M9: INFRA
A10: 6 | B10: Phase 1 - Scan Infrastructure | C10: Database schema | D10: ada_scans, ada_findings, ada_baselines tables with tenant_id on every row. Idempotent init, consistent with existing db.ts pattern. | E10: Backend eng | F10: 4 | G10: =MAX(1,ROUNDUP(F10/Assumptions!$B$8,0)) -> 3 | H10: =WORKDAY(I9,1) -> 46296 | I10: =WORKDAY(H10,G10-1) -> 46300 | K10: High | L10: backend/src/db.ts | M10: INFRA
A11: 7 | B11: Phase 1 - Scan Infrastructure | C11: Scan orchestration service | D11: ada-scan.service.ts: per-page fan-out, partial-failure tolerance, resumable runs, cost accounting. | E11: Backend eng | F11: 6 | G11: =MAX(1,ROUNDUP(F11/Assumptions!$B$8,0)) -> 4 | H11: =WORKDAY(I10,1) -> 46301 | I11: =WORKDAY(H11,G11-1) -> 46304 | K11: Medium | L11: new: backend/src/services/ada-scan.service.ts | M11: INFRA
A12: 8 | B12: Phase 1 - Scan Infrastructure | C12: Worker task type | D12: New task type in the polling worker so scans run out-of-process like pipeline stages do. | E12: Backend eng | F12: 4 | G12: =MAX(1,ROUNDUP(F12/Assumptions!$B$8,0)) -> 3 | H12: =WORKDAY(I11,1) -> 46307 | I12: =WORKDAY(H12,G12-1) -> 46309 | K12: High | L12: backend/src/worker/, routes/pipeline-worker.routes.ts | M12: INFRA
A13: 9 | B13: Phase 1 - Scan Infrastructure | C13: SSE progress events | D13: Emit per-page scan progress to the frontend over the existing SSE channel. | E13: Backend eng | F13: 2 | G13: =MAX(1,ROUNDUP(F13/Assumptions!$B$8,0)) -> 2 | H13: =WORKDAY(I12,1) -> 46310 | I13: =WORKDAY(H13,G13-1) -> 46311 | K13: High | L13: backend/src/services/sse-manager.ts | M13: INFRA
A14: 10 | B14: Phase 1 - Scan Infrastructure | C14: REST API | D14: ada.routes.ts: start scan, poll status, list findings, fetch one finding. Tenant-scoped, mounted in index.ts. | E14: Backend eng | F14: 4 | G14: =MAX(1,ROUNDUP(F14/Assumptions!$B$8,0)) -> 3 | H14: =WORKDAY(I13,1) -> 46314 | I14: =WORKDAY(H14,G14-1) -> 46316 | J14: M2 - Scan pipeline runs end-to-end | K14: High | L14: new: backend/src/routes/ada.routes.ts | M14: INFRA
A15: 11 | B15: Phase 2 - Deterministic Checks | C15: Accessibility engine (ADA / WCAG) | D15: @axe-core/playwright per page. Map each violation to its WCAG 2.2 success criterion. Alt text, ARIA, focus order, keyboard traps, contrast. | E15: Backend eng | F15: 6 | G15: =MAX(1,ROUNDUP(F15/Assumptions!$B$8,0)) -> 4 | H15: =WORKDAY(I14,1) -> 46317 | I15: =WORKDAY(H15,G15-1) -> 46322 | K15: High | L15: new: backend/src/services/ada-a11y.service.ts | M15: A11Y
A16: 12 | B16: Phase 2 - Deterministic Checks | C16: Broken & dead link checker | D16: Crawl every internal and outbound link. Report 404s, redirect chains, timeouts and unreachable targets with the referring page. | E16: Backend eng | F16: 5 | G16: =MAX(1,ROUNDUP(F16/Assumptions!$B$8,0)) -> 4 | H16: =WORKDAY(I15,1) -> 46323 | I16: =WORKDAY(H16,G16-1) -> 46328 | K16: High | L16: new: backend/src/services/ada-links.service.ts | M16: LINKS
A17: 13 | B17: Phase 2 - Deterministic Checks | C17: Web best-practice checks | D17: Semantic HTML, page metadata, image sizing, console errors, mixed content. Lighthouse-style rule set. | E17: Backend eng | F17: 5 | G17: =MAX(1,ROUNDUP(F17/Assumptions!$B$8,0)) -> 4 | H17: =WORKDAY(I16,1) -> 46329 | I17: =WORKDAY(H17,G17-1) -> 46332 | K17: Medium | L17: new: backend/src/services/ada-bestpractice.service.ts | M17: BESTPRACTICE
A18: 14 | B18: Phase 2 - Deterministic Checks | C18: Finding normalisation | D18: Common finding shape, severity model, cross-page dedupe, element attribution (selector + screenshot region). | E18: Backend eng | F18: 4 | G18: =MAX(1,ROUNDUP(F18/Assumptions!$B$8,0)) -> 3 | H18: =WORKDAY(I17,1) -> 46335 | I18: =WORKDAY(H18,G18-1) -> 46337 | J18: M3 - MVP: a11y + links shippable | K18: Medium | L18: new: backend/src/services/ada-findings.service.ts | M18: REPORT
A19: 15 | B19: Phase 3 - Visual & Design QA | C19: Computed-style harvester | D19: Capture per-element computed styles and bounding boxes at each viewport in the matrix. Shared input for the four visual checks. | E19: Backend eng | F19: 5 | G19: =MAX(1,ROUNDUP(F19/Assumptions!$B$8,0)) -> 4 | H19: =WORKDAY(I18,1) -> 46338 | I19: =WORKDAY(H19,G19-1) -> 46343 | K19: Medium | L19: new: backend/src/services/ada-visual.service.ts | M19: ALIGN
A20: 16 | B20: Phase 3 - Visual & Design QA | C20: Font consistency check | D20: Cluster font family/weight/size across pages, flag outliers against the dominant set or the declared type scale. | E20: Backend eng | F20: 5 | G20: =MAX(1,ROUNDUP(F20/Assumptions!$B$8,0)) -> 4 | H20: =WORKDAY(I19,1) -> 46344 | I20: =WORKDAY(H20,G20-1) -> 46349 | K20: Medium | L20: ada-visual.service.ts | M20: FONT
A21: 17 | B21: Phase 3 - Visual & Design QA | C21: Colour accuracy check | D21: Compare rendered hex values against the approved palette / design tokens. Flag near-miss and off-palette colours. | E21: Backend eng | F21: 5 | G21: =MAX(1,ROUNDUP(F21/Assumptions!$B$8,0)) -> 4 | H21: =WORKDAY(I20,1) -> 46350 | I21: =WORKDAY(H21,G21-1) -> 46353 | K21: Medium | L21: ada-visual.service.ts | M21: COLOR
A22: 18 | B22: Phase 3 - Visual & Design QA | C22: Overlapping element detection | D22: Bounding-box collision and clipping detection. Flag controls that overlap or become unclickable at any viewport. | E22: Backend eng | F22: 6 | G22: =MAX(1,ROUNDUP(F22/Assumptions!$B$8,0)) -> 4 | H22: =WORKDAY(I21,1) -> 46356 | I22: =WORKDAY(H22,G22-1) -> 46359 | K22: Low | L22: ada-visual.service.ts | M22: OVERLAP
A23: 19 | B23: Phase 3 - Visual & Design QA | C23: UI alignment analysis | D23: Detect misaligned elements, uneven spacing and broken grid layouts across breakpoints. Highest false-positive risk. | E23: Backend eng | F23: 7 | G23: =MAX(1,ROUNDUP(F23/Assumptions!$B$8,0)) -> 5 | H23: =WORKDAY(I22,1) -> 46360 | I23: =WORKDAY(H23,G23-1) -> 46366 | K23: Low | L23: ada-visual.service.ts | M23: ALIGN
A24: 20 | B24: Phase 3 - Visual & Design QA | C24: Design-standard ingestion | D24: Let a tenant upload a style guide / design-token file. Parse into a comparable rule set. Kiro-style project standards. | E24: Backend eng | F24: 5 | G24: =MAX(1,ROUNDUP(F24/Assumptions!$B$8,0)) -> 4 | H24: =WORKDAY(I23,1) -> 46367 | I24: =WORKDAY(H24,G24-1) -> 46372 | K24: Medium | L24: new: backend/src/services/ada-standards.service.ts | M24: STYLEGUIDE
A25: 21 | B25: Phase 3 - Visual & Design QA | C25: Style-guide adherence check | D25: Compare the live UI against the ingested standards and component rules. Report deviations per page. | E25: Backend eng | F25: 6 | G25: =MAX(1,ROUNDUP(F25/Assumptions!$B$8,0)) -> 4 | H25: =WORKDAY(I24,1) -> 46373 | I25: =WORKDAY(H25,G25-1) -> 46378 | K25: Low | L25: ada-standards.service.ts | M25: STYLEGUIDE
A26: 22 | B26: Phase 3 - Visual & Design QA | C26: Visual-check tuning | D26: False-positive reduction against two or three real client sites. Threshold calibration. Expect iteration here. | E26: Backend eng + QA | F26: 6 | G26: =MAX(1,ROUNDUP(F26/Assumptions!$B$8,0)) -> 4 | H26: =WORKDAY(I25,1) -> 46379 | I26: =WORKDAY(H26,G26-1) -> 46384 | J26: M4 - Visual & design QA complete | K26: Low | L26: ada-visual.service.ts | M26: ALIGN
A27: 23 | B27: Phase 4 - Scoring & Reporting | C27: Scoring model | D27: Per-category scores and weighting into one overall health score. Documented and tenant-overridable. | E27: Backend eng | F27: 4 | G27: =MAX(1,ROUNDUP(F27/Assumptions!$B$8,0)) -> 3 | H27: =WORKDAY(I26,1) -> 46385 | I27: =WORKDAY(H27,G27-1) -> 46387 | K27: Medium | L27: new: backend/src/services/ada-score.service.ts | M27: REPORT
A28: 24 | B28: Phase 4 - Scoring & Reporting | C28: Website health report | D28: Scored audit: findings by page and severity, with evidence (screenshot + selector) attached to each. | E28: Backend eng | F28: 6 | G28: =MAX(1,ROUNDUP(F28/Assumptions!$B$8,0)) -> 4 | H28: =WORKDAY(I27,1) -> 46388 | I28: =WORKDAY(H28,G28-1) -> 46393 | K28: Medium | L28: backend/src/services/artifact-report.service.ts | M28: REPORT
A29: 25 | B29: Phase 4 - Scoring & Reporting | C29: Trend across runs | D29: Compare a scan to its predecessors. Surface regressions and improvements per category. | E29: Backend eng | F29: 4 | G29: =MAX(1,ROUNDUP(F29/Assumptions!$B$8,0)) -> 3 | H29: =WORKDAY(I28,1) -> 46394 | I29: =WORKDAY(H29,G29-1) -> 46398 | K29: Medium | L29: backend/src/services/report-archive.service.ts | M29: REPORT
A30: 26 | B30: Phase 4 - Scoring & Reporting | C30: Export & notification | D30: PDF/Excel export of the health report and email delivery on scan completion. | E30: Backend eng | F30: 4 | G30: =MAX(1,ROUNDUP(F30/Assumptions!$B$8,0)) -> 3 | H30: =WORKDAY(I29,1) -> 46399 | I30: =WORKDAY(H30,G30-1) -> 46401 | J30: M5 - Health report GA-ready | K30: High | L30: backend/src/services/email.service.ts | M30: REPORT
A31: 27 | B31: Phase 5 - Frontend & UX | C31: Replace the placeholder flow | D31: Swap the ada-preview screen for the real wizard: app/URL picker, viewport and depth config, scan trigger. | E31: Frontend eng | F31: 5 | G31: =MAX(1,ROUNDUP(F31/Assumptions!$B$8,0)) -> 4 | H31: =WORKDAY(I30,1) -> 46402 | I31: =WORKDAY(H31,G31-1) -> 46407 | K31: High | L31: frontend/src/pages/ChatPage.tsx (ADA_SUITES, ada-preview) | M31: UI
A32: 28 | B32: Phase 5 - Frontend & UX | C32: Live scan progress | D32: Per-page progress in the chat panel and the pipeline sidebar, driven by SSE. | E32: Frontend eng | F32: 4 | G32: =MAX(1,ROUNDUP(F32/Assumptions!$B$8,0)) -> 3 | H32: =WORKDAY(I31,1) -> 46408 | I32: =WORKDAY(H32,G32-1) -> 46412 | K32: High | L32: frontend/src/pages/ChatPage.tsx | M32: UI
A33: 29 | B33: Phase 5 - Frontend & UX | C33: Findings explorer | D33: Browse and filter findings by severity, category and page. Evidence viewer with the offending element highlighted. | E33: Frontend eng | F33: 7 | G33: =MAX(1,ROUNDUP(F33/Assumptions!$B$8,0)) -> 5 | H33: =WORKDAY(I32,1) -> 46413 | I33: =WORKDAY(H33,G33-1) -> 46419 | K33: Medium | L33: new: frontend/src/pages/AdaFindingsPage.tsx | M33: UI
A34: 30 | B34: Phase 5 - Frontend & UX | C34: Report page & Reports integration | D34: Health report view, plus ADA runs listed alongside existing runs on the Reports page. | E34: Frontend eng | F34: 5 | G34: =MAX(1,ROUNDUP(F34/Assumptions!$B$8,0)) -> 4 | H34: =WORKDAY(I33,1) -> 46420 | I34: =WORKDAY(H34,G34-1) -> 46423 | K34: High | L34: frontend/src/pages/ReportsPage.tsx | M34: UI
A35: 31 | B35: Phase 5 - Frontend & UX | C35: Bug Tracker integration | D35: Raise a ticket straight from a finding, reusing the existing bug registration path. | E35: Frontend eng | F35: 3 | G35: =MAX(1,ROUNDUP(F35/Assumptions!$B$8,0)) -> 2 | H35: =WORKDAY(I34,1) -> 46426 | I35: =WORKDAY(H35,G35-1) -> 46427 | K35: High | L35: frontend/src/pages/BugTrackerPage.tsx, routes/bugs.routes.ts | M35: UI
A36: 32 | B36: Phase 5 - Frontend & UX | C36: Feature toggle & role gating | D36: Gate the suite behind a toggle and the existing role model so it can ship dark and enable per tenant. | E36: Frontend eng | F36: 2 | G36: =MAX(1,ROUNDUP(F36/Assumptions!$B$8,0)) -> 2 | H36: =WORKDAY(I35,1) -> 46428 | I36: =WORKDAY(H36,G36-1) -> 46429 | J36: M6 - Feature complete (internal) | K36: High | L36: frontend/src/pages/FeatureTogglesPage.tsx, components/FeatureGate.tsx | M36: UI
A37: 33 | B37: Phase 6 - Hardening & Release | C37: Multi-tenancy audit | D37: Verify tenant_id filtering on every new query and route. Non-negotiable before any tenant sees it. | E37: Tech lead | F37: 2 | G37: =MAX(1,ROUNDUP(F37/Assumptions!$B$8,0)) -> 2 | H37: =WORKDAY(I36,1) -> 46430 | I37: =WORKDAY(H37,G37-1) -> 46433 | K37: High | L37: backend/src/routes/ada.routes.ts, db.ts | M37: HARDEN
A38: 34 | B38: Phase 6 - Hardening & Release | C38: Budget & performance guards | D38: Page caps, timeouts, cost ceilings and convergence guards so a large site cannot run away with the worker or the API spend. | E38: Backend eng | F38: 4 | G38: =MAX(1,ROUNDUP(F38/Assumptions!$B$8,0)) -> 3 | H38: =WORKDAY(I37,1) -> 46434 | I38: =WORKDAY(H38,G38-1) -> 46436 | K38: Medium | L38: backend/config/pipeline-definition.json | M38: HARDEN
A39: 35 | B39: Phase 6 - Hardening & Release | C39: Security review | D39: Credential handling for authenticated scans, encrypted at rest via the existing crypto util. Scan-target allowlisting. | E39: Tech lead | F39: 3 | G39: =MAX(1,ROUNDUP(F39/Assumptions!$B$8,0)) -> 2 | H39: =WORKDAY(I38,1) -> 46437 | I39: =WORKDAY(H39,G39-1) -> 46440 | K39: High | L39: backend/src/utils/crypto.ts | M39: HARDEN
A40: 36 | B40: Phase 6 - Hardening & Release | C40: Test coverage | D40: Unit tests per check plus an integration test that scans a fixture site with known defects. | E40: QA + eng | F40: 5 | G40: =MAX(1,ROUNDUP(F40/Assumptions!$B$8,0)) -> 4 | H40: =WORKDAY(I39,1) -> 46441 | I40: =WORKDAY(H40,G40-1) -> 46444 | K40: Medium | L40: backend/tests/ | M40: HARDEN
A41: 37 | B41: Phase 6 - Hardening & Release | C41: Documentation | D41: User guide, CLAUDE.md architecture update, operational runbook for failed scans. | E41: Tech lead | F41: 3 | G41: =MAX(1,ROUNDUP(F41/Assumptions!$B$8,0)) -> 2 | H41: =WORKDAY(I40,1) -> 46447 | I41: =WORKDAY(H41,G41-1) -> 46448 | K41: High | L41: CLAUDE.md | M41: HARDEN
...

Sheet Milestones
A1: Milestones
A2: Dates pull from the Roadmap tab. Cumulative effort is every task up to and including the milestone.
A4: Milestone | B4: Phase | C4: Definition of done | D4: Date | E4: Cumulative effort (person-days) | F4: Confidence
A5: M1 - Approach approved | B5: Phase 0 - Discovery & Spike | C5: Approach validated by spike, scope and acceptance criteria signed off, schema designed. | D5: =Roadmap!I8 -> 46289 | E5: =SUM(Roadmap!F5:F8) -> 12 | F5: High
A6: M2 - Scan pipeline runs end-to-end | B6: Phase 1 - Scan Infrastructure | C6: A scan can be triggered, crawls the target, records pages and streams progress - no checks wired yet. | D6: =Roadmap!I14 -> 46316 | E6: =SUM(Roadmap!F5:F14) -> 38 | F6: High
A7: M3 - MVP: a11y + links shippable | B7: Phase 2 - Deterministic Checks | C7: MVP: accessibility (WCAG 2.2 AA), broken links and best-practice checks produce real findings. Recommended first release. | D7: =Roadmap!I18 -> 46337 | E7: =SUM(Roadmap!F5:F18) -> 58 | F7: High
A8: M4 - Visual & design QA complete | B8: Phase 3 - Visual & Design QA | C8: All four visual checks plus style-guide adherence running and tuned against real sites. | D8: =Roadmap!I26 -> 46384 | E8: =SUM(Roadmap!F5:F26) -> 103 | F8: Low
A9: M5 - Health report GA-ready | B9: Phase 4 - Scoring & Reporting | C9: Scored website health report with evidence, trend comparison, export and email. | D9: =Roadmap!I30 -> 46401 | E9: =SUM(Roadmap!F5:F30) -> 121 | F9: Medium
A10: M6 - Feature complete (internal) | B10: Phase 5 - Frontend & UX | C10: Full UI: scan wizard, live progress, findings explorer, report page, bug-tracker hand-off. Behind a toggle. | D10: =Roadmap!I36 -> 46429 | E10: =SUM(Roadmap!F5:F36) -> 147 | F10: Medium
A11: M7 - GA release | B11: Phase 6 - Hardening & Release | C11: Multi-tenancy, security and performance signed off. Piloted with a client and enabled in production. | D11: =Roadmap!I43 -> 46456 | E11: =SUM(Roadmap!F5:F43) -> 171 | F11: Medium
A13: M3 is the recommended first release: highest-confidence checks, real user value, and it lands well before the full suite.

Sheet Scope
A1: Scope - the nine checks
A2: Mirrors ADA_SUITES in frontend/src/pages/ChatPage.tsx (line ~113), which is what the placeholder screen renders. Effort pulls from the Roadmap tab by scope tag.
A4: Check (as shown in the UI) | B4: Group on screen | C4: Scope tag | D4: Delivered in phase | E4: What it does | F4: Technical approach | G4: Confidence | H4: Effort (person-days)
A5: Broken & dead links / 404s | B5: Links & site health | C5: LINKS | D5: Phase 2 | E5: Crawl every internal and outbound link; report 404s, redirect chains and unreachable targets. | F5: Custom crawler on the existing Playwright/Chromium setup. Well-understood problem. | G5: High | H5: =SUMIF(Roadmap!$M$5:$M$43,C5,Roadmap!$F$5:$F$43) -> 5
A6: ADA / accessibility compliance | B6: Accessibility & compliance | C6: A11Y | D6: Phase 2 | E6: WCAG 2.2 AA: alt text, ARIA roles, focus order, keyboard traps, contrast - each mapped to a success criterion. | F6: axe-core via @axe-core/playwright. Mature, deterministic rule engine - the one check with an off-the-shelf answer. | G6: High | H6: =SUMIF(Roadmap!$M$5:$M$43,C6,Roadmap!$F$5:$F$43) -> 9
A7: UI alignment issues | B7: Visual & design QA | C7: ALIGN | D7: Phase 3 | E7: Misaligned elements, uneven spacing, broken grid layouts across breakpoints. | F7: Bounding-box geometry from the live DOM, or rendered-baseline diff. No standard engine; needs the Phase 0 spike. | G7: Low | H7: =SUMIF(Roadmap!$M$5:$M$43,C7,Roadmap!$F$5:$F$43) -> 22
A8: Inconsistent fonts / font sizes | B8: Visual & design QA | C8: FONT | D8: Phase 3 | E8: Font family, weight and size drift compared page to page. | F8: Computed-style harvest, then clustering against the dominant set or a declared type scale. | G8: Medium | H8: =SUMIF(Roadmap!$M$5:$M$43,C8,Roadmap!$F$5:$F$43) -> 5
A9: Incorrect colours / hex codes | B9: Visual & design QA | C9: COLOR | D9: Phase 3 | E9: Rendered colours checked against the approved brand palette and design tokens. | F9: Computed-style harvest, compared to an ingested token set. Needs the palette as input. | G9: Medium | H9: =SUMIF(Roadmap!$M$5:$M$43,C9,Roadmap!$F$5:$F$43) -> 5
A10: Buttons or elements overlapping | B10: Visual & design QA | C10: OVERLAP | D10: Phase 3 | E10: Controls that collide, clip or become unclickable at any viewport. | F10: Bounding-box collision detection plus hit-testing. Overlap is common and often intentional - tuning matters. | G10: Low | H10: =SUMIF(Roadmap!$M$5:$M$43,C10,Roadmap!$F$5:$F$43) -> 6
A11: Style guide / design standards adherence | B11: Visual & design QA | C11: STYLEGUIDE | D11: Phase 3 | E11: The live UI compared against documented design standards and component rules. | F11: Tenant uploads a style guide or token file; agent treats it as the source of truth (Kiro-style steering doc). | G11: Low | H11: =SUMIF(Roadmap!$M$5:$M$43,C11,Roadmap!$F$5:$F$43) -> 11
A12: General web best practices | B12: Accessibility & compliance | C12: BESTPRACTICE | D12: Phase 2 | E12: Semantic HTML, page metadata, image sizing, console errors, mixed content. | F12: Lighthouse-style rule set, implemented directly against the page. | G12: Medium | H12: =SUMIF(Roadmap!$M$5:$M$43,C12,Roadmap!$F$5:$F$43) -> 5
A13: Website health / audit report | B13: Output | C13: REPORT | D13: Phase 4 | E13: One scored audit per run: score per category, findings ranked by severity with page and element, trend across runs. | F13: Scoring model over normalised findings, rendered through the existing report/artifact services. | G13: Medium | H13: =SUMIF(Roadmap!$M$5:$M$43,C13,Roadmap!$F$5:$F$43) -> 22
G14: Checks total | H14: =SUM(H5:H13) -> 90
A16: Note: the checks total (90) is less than the roadmap total (171) because scan infrastructure, frontend and hardening effort is not attributed to any single check. Shared visual tooling (the computed-style harvester, the Phase 0 spike and the tuning pass) is tagged to UI alignment, so that row reads high relative to the three visual checks that also depend on it.

Sheet Risks
A1: Risk register
A2: Ordered by exposure. The top three all sit in Phase 3.
A4: Risk | B4: Likelihood | C4: Impact | D4: Why it matters | E4: Mitigation | F4: Owner
A5: Visual checks produce too many false positives to be usable | B5: High | C5: High | D5: Alignment and overlap have no standard rule engine. A check that cries wolf gets switched off and the phase is wasted. | E5: Phase 0 spike before committing. Budget explicit tuning time (task 22). Ship visual checks behind a per-tenant toggle, warn-only at first. | F5: Tech lead
A6: Phase 3 effort grows beyond estimate | B6: High | C6: Medium | D6: 45 of 171 person-days sit in the least-certain phase. A baseline-diff approach would cost materially more than geometry analysis. | E6: Re-estimate Phase 3 at the M1 gate once the spike lands. Ship M3 first so a Phase 3 overrun does not block all user value. | F6: Tech lead
A7: Style-guide adherence has no input to check against | B7: Medium | C7: High | D7: The check is meaningless unless the tenant actually has documented design standards in a parseable form. Many will not. | E7: Confirm with the pilot client during Phase 0 that a usable style guide or token file exists. Otherwise defer this check. | F7: Product
A8: Scan cost and runtime on large sites | B8: Medium | C8: Medium | D8: Every check runs per page. A large site multiplies browser time and, where the LLM is involved, API spend. | E8: Hard page caps and timeouts from Phase 1 (existing budget-guard pattern). Cost ceiling per scan, surfaced before the run starts. | F8: Backend eng
A9: Authenticated scans need stored credentials | B9: Medium | C9: High | D9: Scanning past a login means holding tenant credentials, which widens the security surface. | E9: Reuse the existing encrypted credential store (backend/src/utils/crypto.ts). Security review is a gating task in Phase 6. | F9: Tech lead
A10: axe-core version drift vs WCAG updates | B10: Low | C10: Medium | D10: Rule sets and success criteria change; findings could go stale or shift between releases. | E10: Pin the axe-core version, record it on every scan, and treat upgrades as a deliberate change with a re-baseline. | F10: Backend eng
A11: Competing priorities pull engineers off the feature | B11: Medium | C11: High | D11: The plan assumes 2 engineers at 80%. Real allocation on this codebase has historically been lumpier. | E11: Track actual capacity against the Assumptions tab; recalculate dates monthly rather than defending the original date. | F11: Delivery lead
